Workbook

Sheet Read me
A1: Competitor tender master: edge, road and rail cost
A2: EDGE RULE (yours): VWLR has a PFT siding with 3 rail lines. A tender is an edge only if the MINE or the PLANT is within 150 km of VWLR. Everything else is context on rivals.
A3: Edge = Yes (an end within 150 km straight-line) | Borderline (150-180 km, about 150 km by road) | No (known ends all far) | Unknown (an end could not be identified from the title).
A4: Locations: mine and plant are matched from the tender title to the nearest listed town. Town coordinates were geocoded on 2026-10-12; the exact mine site is approximate [UNVERIFIED]. Reference point is Raigarh town until you name your siding's railway station (Settings).
A5: Costs per tonne: ROAD = near-end km x road factor x your road rate (+GST, +handling). RAIL = FOIS class 145A base tariff for the far-end km when that end is known, plus GST. FOIS excludes surcharges and siding charges. No tonnage is in the export, so no per-contract figures.
A6: Winner's own cost is unknown: this sheet shows where freight could have been your lever, not who would have won.
A7: Yellow cells are inputs. Everything else is a formula.

Sheet Master
A1: Edge | B1: Basis | C1: Mine (matched) | D1: Mine km | E1: Plant / siding (matched) | F1: Plant km | G1: Nearest end km | H1: TR247 ID | I1: Tender ref | J1: Title | K1: Category | L1: Buyer | M1: State | N1: Tender city | O1: Close date | P1: Stage | Q1: Winner | R1: Tracked rivals bidding | S1: Bidders | T1: Contract Rs Cr | U1: Road leg Rs/t (near end to your siding) | V1: Far-end km | W1: Rail leg Rs/t (your siding to far end, FOIS 145A) | X1: Indicative total Rs/t | Y1: Rate status
A2: Yes | B2: mine = coal company's tender city; siding = same area | C2: Raigarh (tender city) | D2: 0 | E2: Raigarh (tender city) | F2: 0 | G2: 0 | H2: 16341071 | I2: GEM/2025/B/7003513 | J2: handling service, hiring of pay loaders incorporatedfitted with weight sensors for mechanical transfer of crushed coal below100mm in to railway wagons all around the width of b.. | K2: Loading / handling / crushing | L2: South Eastern Coalfields Limited | M2: Chhattisgarh | N2: Raigarh | O2: 46022 | P2: AOC | Q2: G K Associates | R2: G K Associates, Chandan Kumar Singh | S2: 4 named / 4 | T2: 5.39 | U2: =IF(ISNUMBER(G2),MAX(MAX(G2,Settings!$B$13)*Settings!$B$7*Settings!$B$5,IF(ISNUMBER(Settings!$B$12),Settings!$B$12,0))*(1+IF(Settings!$B$11="Y",0,Settings!$B$10/100))+N(Settings!$B$9),"") | W2: =IF(ISNUMBER(V2),IF(V2*Settings!$B$8>1000,"beyond table",IFERROR(LOOKUP(V2*Settings!$B$8,'FOIS 145A'!$A$2:$A$22,'FOIS 145A'!$C$2:$C$22)*(1+IF(Settings!$B$11="Y",0,Settings!$B$10/100)),"")),"") | X2: =IF(AND(ISNUMBER(U2),ISNUMBER(W2)),U2+W2,"") | Y2: =Settings!$B$6
A3: Yes | B3: mine = coal company's tender city; siding = same area | C3: Raigarh (tender city) | D3: 0 | E3: Raigarh (tender city) | F3: 0 | G3: 0 | H3: 15858739 | I3: GEM/2025/B/6353919 | J3: handling ,transport and other mining services - percentagequote based - handling & transport service, ob removal,coal extraction, composite work ob removal, loading andtransportation of coal , extract | K3: Mining services (OB / extraction) | L3: South Eastern Coalfields Limited | M3: Chhattisgarh | N3: Raigarh | O3: 45885 | P3: AOC | Q3: Sical Logistics Limited | R3: Caliber Mining and Logistics | S3: 5 named / 25 | T3: 4038.18 | U3: =IF(ISNUMBER(G3),MAX(MAX(G3,Settings!$B$13)*Settings!$B$7*Settings!$B$5,IF(ISNUMBER(Settings!$B$12),Settings!$B$12,0))*(1+IF(Settings!$B$11="Y",0,Settings!$B$10/100))+N(Settings!$B$9),"") | W3: =IF(ISNUMBER(V3),IF(V3*Settings!$B$8>1000,"beyond table",IFERROR(LOOKUP(V3*Settings!$B$8,'FOIS 145A'!$A$2:$A$22,'FOIS 145A'!$C$2:$C$22)*(1+IF(Settings!$B$11="Y",0,Settings!$B$10/100)),"")),"") | X3: =IF(AND(ISNUMBER(U3),ISNUMBER(W3)),U3+W3,"") | Y3: =Settings!$B$6
A4: Yes | B4: plant = tender city | E4: Sundargarh district (IB Valley / Hemgir) (tender city) | F4: 32 | G4: 32 | H4: 14060255 | I4: GEM/2025/B/6194484 | J4: domestic coal for ntpc | K4: Coal supply | L4: National Thermal Power Corporation Limited | M4: Orissa | N4: Sundergarh | O4: 45817 | P4: Financial | Q4: - | R4: Godavari Commodities, Sendoz Impex | S4: 3 named / 3 | U4: =IF(ISNUMBER(G4),MAX(MAX(G4,Settings!$B$13)*Settings!$B$7*Settings!$B$5,IF(ISNUMBER(Settings!$B$12),Settings!$B$12,0))*(1+IF(Settings!$B$11="Y",0,Settings!$B$10/100))+N(Settings!$B$9),"") | W4: =IF(ISNUMBER(V4),IF(V4*Settings!$B$8>1000,"beyond table",IFERROR(LOOKUP(V4*Settings!$B$8,'FOIS 145A'!$A$2:$A$22,'FOIS 145A'!$C$2:$C$22)*(1+IF(Settings!$B$11="Y",0,Settings!$B$10/100)),"")),"") | X4: =IF(AND(ISNUMBER(U4),ISNUMBER(W4)),U4+W4,"") | Y4: =Settings!$B$6
A5: Yes | B5: mine named in title; plant/siding named in title | C5: Hemgir / Manoharpur (Sundargarh) | D5: 32 | E5: Rourkela | F5: 156 | G5: 32 | H5: 17865617 | I5: GEM/2026/B/7514337 | J5: transportation of coal from ocpl manoharpur mines to any privatepublic siding of railways and then loading into (boxn) ir wagons for onward transporatation to nspcl rourkela(hspg siding) | K5: Coal transport (RCR / siding) | L5: Ntpc-Sail Power Company Private Limited | M5: Orissa | N5: Rourkela | O5: 46196 | P5: Financial | Q5: - | R5: Anoop Road Carriers, Bharat Road Carrier, Godavari Commodities, Indermani / Indramani | S5: 5 named / 11 | U5: =IF(ISNUMBER(G5),MAX(MAX(G5,Settings!$B$13)*Settings!$B$7*Settings!$B$5,IF(ISNUMBER(Settings!$B$12),Settings!$B$12,0))*(1+IF(Settings!$B$11="Y",0,Settings!$B$10/100))+N(Settings!$B$9),"") | V5: 156 | W5: =IF(ISNUMBER(V5),IF(V5*Settings!$B$8>1000,"beyond table",IFERROR(LOOKUP(V5*Settings!$B$8,'FOIS 145A'!$A$2:$A$22,'FOIS 145A'!$C$2:$C$22)*(1+IF(Settings!$B$11="Y",0,Settings!$B$10/100)),"")),"") | X5: =IF(AND(ISNUMBER(U5),ISNUMBER(W5)),U5+W5,"") | Y5: =Settings!$B$6
A6: Yes | B6: mine = coal company's tender city; siding = same area | C6: Sundargarh district (IB Valley / Hemgir) (tender city) | D6: 32 | E6: Sundargarh district (IB Valley / Hemgir) (tender city) | F6: 32 | G6: 32 | H6: 17284903 | I6: GEM/2026/B/7448459 | J6: hiring of payloaders and tippers for loading and transportation of coal from stock to siding | K6: Coal transport (RCR / siding) | L6: Mahanadi Coalfields Limited | M6: Orissa | N6: Sundergarh | O6: 46144 | P6: AOC | Q6: Jagshobha Logistics Llp | S6: 5 named / 7 | T6: 2.07 | U6: =IF(ISNUMBER(G6),MAX(MAX(G6,Settings!$B$13)*Settings!$B$7*Settings!$B$5,IF(ISNUMBER(Settings!$B$12),Settings!$B$12,0))*(1+IF(Settings!$B$11="Y",0,Settings!$B$10/100))+N(Settings!$B$9),"") | W6: =IF(ISNUMBER(V6),IF(V6*Settings!$B$8>1000,"beyond table",IFERROR(LOOKUP(V6*Settings!$B$8,'FOIS 145A'!$A$2:$A$22,'FOIS 145A'!$C$2:$C$22)*(1+IF(Settings!$B$11="Y",0,Settings!$B$10/100)),"")),"") | X6: =IF(AND(ISNUMBER(U6),ISNUMBER(W6)),U6+W6,"") | Y6: =Settings!$B$6
A7: Yes | B7: mine = coal company's tender city; siding = same area | C7: Sundargarh district (IB Valley / Hemgir) (tender city) | D7: 32 | E7: Sundargarh district (IB Valley / Hemgir) (tender city) | F7: 32 | G7: 32 | H7: 16121661 | I7: GEM/2025/B/6910835 | J7: hiring of pay loaders and tippers for loading and transportation of coal from face to siding | K7: Coal transport (RCR / siding) | L7: Mahanadi Coalfields Limited | M7: Orissa | N7: Sundergarh | O7: 46003 | P7: AOC | Q7: Matarani Resources Private Limited | S7: 3 named / 3 | T7: 6.17 | U7: =IF(ISNUMBER(G7),MAX(MAX(G7,Settings!$B$13)*Settings!$B$7*Settings!$B$5,IF(ISNUMBER(Settings!$B$12),Settings!$B$12,0))*(1+IF(Settings!$B$11="Y",0,Settings!$B$10/100))+N(Settings!$B$9),"") | W7: =IF(ISNUMBER(V7),IF(V7*Settings!$B$8>1000,"beyond table",IFERROR(LOOKUP(V7*Settings!$B$8,'FOIS 145A'!$A$2:$A$22,'FOIS 145A'!$C$2:$C$22)*(1+IF(Settings!$B$11="Y",0,Settings!$B$10/100)),"")),"") | X7: =IF(AND(ISNUMBER(U7),ISNUMBER(W7)),U7+W7,"") | Y7: =Settings!$B$6
A8: Yes | B8: mine named in title; plant/siding named in title | C8: Hemgir / Manoharpur (Sundargarh) | D8: 32 | E8: Hemgir / Manoharpur (Sundargarh) | F8: 32 | G8: 32 | H8: 17034496 | I8: 2026_OCAPL_127805_1 | J8: transportation of coal from manoharpur coal mines to ntpc, darlipali, sundargarh by road | K8: Coal transport (road) | L8: Odisha Coal And Power Limited | M8: Orissa | N8: Sundergarh | O8: 46121 | P8: Technical | Q8: - | R8: Vedvyas Logistic | S8: 5 named / 5 | U8: =IF(ISNUMBER(G8),MAX(MAX(G8,Settings!$B$13)*Settings!$B$7*Settings!$B$5,IF(ISNUMBER(Settings!$B$12),Settings!$B$12,0))*(1+IF(Settings!$B$11="Y",0,Settings!$B$10/100))+N(Settings!$B$9),"") | W8: =IF(ISNUMBER(V8),IF(V8*Settings!$B$8>1000,"beyond table",IFERROR(LOOKUP(V8*Settings!$B$8,'FOIS 145A'!$A$2:$A$22,'FOIS 145A'!$C$2:$C$22)*(1+IF(Settings!$B$11="Y",0,Settings!$B$10/100)),"")),"") | X8: =IF(AND(ISNUMBER(U8),ISNUMBER(W8)),U8+W8,"") | Y8: =Settings!$B$6
A9: Yes | B9: mine named in title; plant = tender city | C9: Hemgir / Manoharpur (Sundargarh) | D9: 32 | E9: Rourkela (tender city) | F9: 156 | G9: 32 | H9: 14138047 | I9: GEM/2025/B/6302813 | J9: transportation of coal from ocpl manoharpur mines | K9: Coal transport (road) | L9: Ntpc-Sail Power Company Private Limited | M9: Orissa | N9: Rourkela | O9: 45824 | P9: AOC | Q9: Orissa Transport Co | R9: Anoop Road Carriers, Tirupati Minerals | S9: 4 named / 4 | T9: 0.39 | U9: =IF(ISNUMBER(G9),MAX(MAX(G9,Settings!$B$13)*Settings!$B$7*Settings!$B$5,IF(ISNUMBER(Settings!$B$12),Settings!$B$12,0))*(1+IF(Settings!$B$11="Y",0,Settings!$B$10/100))+N(Settings!$B$9),"") | V9: 156 | W9: =IF(ISNUMBER(V9),IF(V9*Settings!$B$8>1000,"beyond table",IFERROR(LOOKUP(V9*Settings!$B$8,'FOIS 145A'!$A$2:$A$22,'FOIS 145A'!$C$2:$C$22)*(1+IF(Settings!$B$11="Y",0,Settings!$B$10/100)),"")),"") | X9: =IF(AND(ISNUMBER(U9),ISNUMBER(W9)),U9+W9,"") | Y9: =Settings!$B$6
A10: Yes | B10: mine named in title; plant = tender city | C10: Hemgir / Manoharpur (Sundargarh) | D10: 32 | E10: Rourkela (tender city) | F10: 156 | G10: 32 | H10: 13961330 | I10: GEM/2025/B/6196170 | J10: transportation of coal from ocpl manoharpur mines to any private/public s | K10: Coal transport (road) | L10: Ntpc-Sail Power Company Private Limited | M10: Orissa | N10: Rourkela | O10: 45810 | P10: Financial | Q10: - | R10: Advika Logistics, Anoop Road Carriers, Godavari Commodities | S10: 5 named / 20 | U10: =IF(ISNUMBER(G10),MAX(MAX(G10,Settings!$B$13)*Settings!$B$7*Settings!$B$5,IF(ISNUMBER(Settings!$B$12),Settings!$B$12,0))*(1+IF(Settings!$B$11="Y",0,Settings!$B$10/100))+N(Settings!$B$9),"") | V10: 156 | W10: =IF(ISNUMBER(V10),IF(V10*Settings!$B$8>1000,"beyond table",IFERROR(LOOKUP(V10*Settings!$B$8,'FOIS 145A'!$A$2:$A$22,'FOIS 145A'!$C$2:$C$22)*(1+IF(Settings!$B$11="Y",0,Settings!$B$10/100)),"")),"") | X10: =IF(AND(ISNUMBER(U10),ISNUMBER(W10)),U10+W10,"") | Y10: =Settings!$B$6
A11: Yes | B11: mine named in title; plant = tender city | C11: Hemgir / Manoharpur (Sundargarh) | D11: 32 | E11: Rourkela (tender city) | F11: 156 | G11: 32 | H11: 13168942 | I11: GEM/2025/B/6073786 | J11: transportation of coal from ocpl manoharpur mines to any privatepublic si | K11: Coal transport (road) | L11: Ntpc-Sail Power Company Private Limited | M11: Orissa | N11: Rourkela | O11: 45750 | P11: AOC | Q11: Alps Mining Services Private Limited | R11: Anoop Road Carriers, Tirupati Minerals | S11: 3 named / 3 | T11: 0.4 | U11: =IF(ISNUMBER(G11),MAX(MAX(G11,Settings!$B$13)*Settings!$B$7*Settings!$B$5,IF(ISNUMBER(Settings!$B$12),Settings!$B$12,0))*(1+IF(Settings!$B$11="Y",0,Settings!$B$10/100))+N(Settings!$B$9),"") | V11: 156 | W11: =IF(ISNUMBER(V11),IF(V11*Settings!$B$8>1000,"beyond table",IFERROR(LOOKUP(V11*Settings!$B$8,'FOIS 145A'!$A$2:$A$22,'FOIS 145A'!$C$2:$C$22)*(1+IF(Settings!$B$11="Y",0,Settings!$B$10/100)),"")),"") | X11: =IF(AND(ISNUMBER(U11),ISNUMBER(W11)),U11+W11,"") | Y11: =Settings!$B$6
A12: Yes | B12: mine = coal company's tender city; siding = same area | C12: Sundargarh district (IB Valley / Hemgir) (tender city) | D12: 32 | E12: Sundargarh district (IB Valley / Hemgir) (tender city) | F12: 32 | G12: 32 | H12: 12921764 | I12: GEM/2025/B/5954457 | J12: loading of road sale tippe | K12: Loading / handling / crushing | L12: Mahanadi Coalfields Limited | M12: Orissa | N12: Sundergarh | O12: 45719 | P12: AOC | Q12: Millennium Suppliers Private Limited | S12: 5 named / 12 | T12: 26.98 | U12: =IF(ISNUMBER(G12),MAX(MAX(G12,Settings!$B$13)*Settings!$B$7*Settings!$B$5,IF(ISNUMBER(Settings!$B$12),Settings!$B$12,0))*(1+IF(Settings!$B$11="Y",0,Settings!$B$10/100))+N(Settings!$B$9),"") | W12: =IF(ISNUMBER(V12),IF(V12*Settings!$B$8>1000,"beyond table",IFERROR(LOOKUP(V12*Settings!$B$8,'FOIS 145A'!$A$2:$A$22,'FOIS 145A'!$C$2:$C$22)*(1+IF(Settings!$B$11="Y",0,Settings!$B$10/100)),"")),"") | X12: =IF(AND(ISNUMBER(U12),ISNUMBER(W12)),U12+W12,"") | Y12: =Settings!$B$6
A13: Yes | B13: mine = coal company's tender city; siding = same area | C13: Sundargarh district (IB Valley / Hemgir) (tender city) | D13: 32 | E13: Sundargarh district (IB Valley / Hemgir) (tender city) | F13: 32 | G13: 32 | H13: 15025805 | I13: GEM/2025/B/6419957 | J13: hiring of pay loaders and | K13: Other | L13: Mahanadi Coalfields Limited | M13: Orissa | N13: Sundergarh | O13: 45859 | P13: AOC | Q13: Matarani Resources Private Limited | R13: Saikrupa Coal Supplier | S13: 3 named / 3 | T13: 7.1 | U13: =IF(ISNUMBER(G13),MAX(MAX(G13,Settings!$B$13)*Settings!$B$7*Settings!$B$5,IF(ISNUMBER(Settings!$B$12),Settings!$B$12,0))*(1+IF(Settings!$B$11="Y",0,Settings!$B$10/100))+N(Settings!$B$9),"") | W13: =IF(ISNUMBER(V13),IF(V13*Settings!$B$8>1000,"beyond table",IFERROR(LOOKUP(V13*Settings!$B$8,'FOIS 145A'!$A$2:$A$22,'FOIS 145A'!$C$2:$C$22)*(1+IF(Settings!$B$11="Y",0,Settings!$B$10/100)),"")),"") | X13: =IF(AND(ISNUMBER(U13),ISNUMBER(W13)),U13+W13,"") | Y13: =Settings!$B$6
A14: Yes | B14: mine = coal company's tender city; siding = same area | C14: Sundargarh district (IB Valley / Hemgir) (tender city) | D14: 32 | E14: Sundargarh district (IB Valley / Hemgir) (tender city) | F14: 32 | G14: 32 | H14: 14395678 | I14: GEM/2025/B/6315435 | J14: extraction of coal/coal me | K14: Other | L14: Mahanadi Coalfields Limited | M14: Orissa | N14: Sundergarh | O14: 45848 | P14: AOC | Q14: Shree Ranisati Mining | S14: 5 named / 9 | T14: 174.14 | U14: =IF(ISNUMBER(G14),MAX(MAX(G14,Settings!$B$13)*Settings!$B$7*Settings!$B$5,IF(ISNUMBER(Settings!$B$12),Settings!$B$12,0))*(1+IF(Settings!$B$11="Y",0,Settings!$B$10/100))+N(Settings!$B$9),"") | W14: =IF(ISNUMBER(V14),IF(V14*Settings!$B$8>1000,"beyond table",IFERROR(LOOKUP(V14*Settings!$B$8,'FOIS 145A'!$A$2:$A$22,'FOIS 145A'!$C$2:$C$22)*(1+IF(Settings!$B$11="Y",0,Settings!$B$10/100)),"")),"") | X14: =IF(AND(ISNUMBER(U14),ISNUMBER(W14)),U14+W14,"") | Y14: =Settings!$B$6
A15: Yes | B15: mine = coal company's tender city; siding = same area | C15: Sundargarh district (IB Valley / Hemgir) (tender city) | D15: 32 | E15: Sundargarh district (IB Valley / Hemgir) (tender city) | F15: 32 | G15: 32 | H15: 13393053 | I15: GEM/2025/B/6129453 | J15: hiring of pay loaders & ti | K15: Other | L15: Mahanadi Coalfields Limited | M15: Orissa | N15: Sundergarh | O15: 45772 | P15: AOC | Q15: Vansh Logistics | S15: 5 named / 9 | T15: 41.46 | U15: =IF(ISNUMBER(G15),MAX(MAX(G15,Settings!$B$13)*Settings!$B$7*Settings!$B$5,IF(ISNUMBER(Settings!$B$12),Settings!$B$12,0))*(1+IF(Settings!$B$11="Y",0,Settings!$B$10/100))+N(Settings!$B$9),"") | W15: =IF(ISNUMBER(V15),IF(V15*Settings!$B$8>1000,"beyond table",IFERROR(LOOKUP(V15*Settings!$B$8,'FOIS 145A'!$A$2:$A$22,'FOIS 145A'!$C$2:$C$22)*(1+IF(Settings!$B$11="Y",0,Settings!$B$10/100)),"")),"") | X15: =IF(AND(ISNUMBER(U15),ISNUMBER(W15)),U15+W15,"") | Y15: =Settings!$B$6
A16: Yes | B16: plant = tender city | E16: Sundargarh district (IB Valley / Hemgir) (tender city) | F16: 32 | G16: 32 | H16: 12797284 | I16: GEM/2025/B/5848728 | J16: providing assistance for om activities at ntpc dlcmp | K16: Other | L16: National Thermal Power Corporation Limited | M16: Orissa | N16: Sundergarh | O16: 45713 | P16: AOC | Q16: M/S A P Construction | S16: 5 named / 9 | T16: 2.19 | U16: =IF(ISNUMBER(G16),MAX(MAX(G16,Settings!$B$13)*Settings!$B$7*Settings!$B$5,IF(ISNUMBER(Settings!$B$12),Settings!$B$12,0))*(1+IF(Settings!$B$11="Y",0,Settings!$B$10/100))+N(Settings!$B$9),"") | W16: =IF(ISNUMBER(V16),IF(V16*Settings!$B$8>1000,"beyond table",IFERROR(LOOKUP(V16*Settings!$B$8,'FOIS 145A'!$A$2:$A$22,'FOIS 145A'!$C$2:$C$22)*(1+IF(Settings!$B$11="Y",0,Settings!$B$10/100)),"")),"") | X16: =IF(AND(ISNUMBER(U16),ISNUMBER(W16)),U16+W16,"") | Y16: =Settings!$B$6
A17: Yes | B17: mine named in title | C17: IB Valley (Jharsuguda) | D17: 47 | G17: 47 | H17: 18286647 | I17: 2026_NTPC_111971_1 | J17: contract for loading and transportation of coal from mcl-ib mine to any designated siding and loading in indian railway wagons for onward transportation to ntpc simhadri. | K17: Coal transport (RCR / siding) | L17: National Thermal Power Corporation Limited | M17: Andhra Pradesh | N17: Visakhapatnam | O17: 46274 | P17: Financial | Q17: - | R17: Anoop Road Carriers, Bharat Road Carrier, Sangita Sales, Swami Fuels | S17: 5 named / 6 | U17: =IF(ISNUMBER(G17),MAX(MAX(G17,Settings!$B$13)*Settings!$B$7*Settings!$B$5,IF(ISNUMBER(Settings!$B$12),Settings!$B$12,0))*(1+IF(Settings!$B$11="Y",0,Settings!$B$10/100))+N(Settings!$B$9),"") | W17: =IF(ISNUMBER(V17),IF(V17*Settings!$B$8>1000,"beyond table",IFERROR(LOOKUP(V17*Settings!$B$8,'FOIS 145A'!$A$2:$A$22,'FOIS 145A'!$C$2:$C$22)*(1+IF(Settings!$B$11="Y",0,Settings!$B$10/100)),"")),"") | X17: =IF(AND(ISNUMBER(U17),ISNUMBER(W17)),U17+W17,"") | Y17: =Settings!$B$6
A18: Yes | B18: mine = coal company's tender city; siding = same area | C18: Brajrajnagar / Jharsuguda (tender city) | D18: 54 | E18: Brajrajnagar / Jharsuguda (tender city) | F18: 54 | G18: 54 | H18: 12706783 | I18: GEM/2025/B/5868534 | J18: loading and transportation | K18: Coal transport (road) | L18: Mahanadi Coalfields Limited | M18: Orissa | N18: Jharsuguda | O18: 45708 | P18: AOC | Q18: Variant Commercial Private Limited | S18: 5 named / 11 | T18: 94.21 | U18: =IF(ISNUMBER(G18),MAX(MAX(G18,Settings!$B$13)*Settings!$B$7*Settings!$B$5,IF(ISNUMBER(Settings!$B$12),Settings!$B$12,0))*(1+IF(Settings!$B$11="Y",0,Settings!$B$10/100))+N(Settings!$B$9),"") | W18: =IF(ISNUMBER(V18),IF(V18*Settings!$B$8>1000,"beyond table",IFERROR(LOOKUP(V18*Settings!$B$8,'FOIS 145A'!$A$2:$A$22,'FOIS 145A'!$C$2:$C$22)*(1+IF(Settings!$B$11="Y",0,Settings!$B$10/100)),"")),"") | X18: =IF(AND(ISNUMBER(U18),ISNUMBER(W18)),U18+W18,"") | Y18: =Settings!$B$6
A19: Yes | B19: mine named in title | C19: Talabira (near Sambalpur/Jharsuguda) | D19: 61 | G19: 61 | H19: 18306349 | I19: 2026_NTPC_111933_1 | J19: transportation of 2 lmt coal from nlc talabira mines to ntpc simhadri through rcr mode - as per sow | K19: Coal transport (RCR / siding) | L19: National Thermal Power Corporation Limited | M19: Chhattisgarh | N19: Raipur | O19: 46288 | P19: Financial | Q19: - | R19: Anoop Road Carriers, Bharat Road Carrier, Mohit Minerals, Sangita Sales | S19: 5 named / 8 | U19: =IF(ISNUMBER(G19),MAX(MAX(G19,Settings!$B$13)*Settings!$B$7*Settings!$B$5,IF(ISNUMBER(Settings!$B$12),Settings!$B$12,0))*(1+IF(Settings!$B$11="Y",0,Settings!$B$10/100))+N(Settings!$B$9),"") | W19: =IF(ISNUMBER(V19),IF(V19*Settings!$B$8>1000,"beyond table",IFERROR(LOOKUP(V19*Settings!$B$8,'FOIS 145A'!$A$2:$A$22,'FOIS 145A'!$C$2:$C$22)*(1+IF(Settings!$B$11="Y",0,Settings!$B$10/100)),"")),"") | X19: =IF(AND(ISNUMBER(U19),ISNUMBER(W19)),U19+W19,"") | Y19: =Settings!$B$6
A20: Yes | B20: mine named in title; plant/siding named in title | C20: Talabira (near Sambalpur/Jharsuguda) | D20: 61 | E20: Talabira (near Sambalpur/Jharsuguda) | F20: 61 | G20: 61 | H20: 18286732 | I20: 2026_NTPC_111957_1 | J20: coal transportation from nlc talabira mines to ntpc telangana(ttgr) - coal transportation from nlc talabira mines to ntpc telangana(ttgr)through rcr mode | K20: Coal transport (RCR / siding) | L20: National Thermal Power Corporation Limited | M20: Chhattisgarh | N20: Raipur | O20: 46287 | P20: AOC | Q20: Swami Fuels Private Limited | R20: Anoop Road Carriers, Swami Fuels, Tirupati Minerals | S20: 4 named / 4 | T20: 6.68 | U20: =IF(ISNUMBER(G20),MAX(MAX(G20,Settings!$B$13)*Settings!$B$7*Settings!$B$5,IF(ISNUMBER(Settings!$B$12),Settings!$B$12,0))*(1+IF(Settings!$B$11="Y",0,Settings!$B$10/100))+N(Settings!$B$9),"") | W20: =IF(ISNUMBER(V20),IF(V20*Settings!$B$8>1000,"beyond table",IFERROR(LOOKUP(V20*Settings!$B$8,'FOIS 145A'!$A$2:$A$22,'FOIS 145A'!$C$2:$C$22)*(1+IF(Settings!$B$11="Y",0,Settings!$B$10/100)),"")),"") | X20: =IF(AND(ISNUMBER(U20),ISNUMBER(W20)),U20+W20,"") | Y20: =Settings!$B$6
A21: Yes | B21: mine named in title | C21: Talabira (near Sambalpur/Jharsuguda) | D21: 61 | G21: 61 | H21: 18222478 | I21: 2026_NTPC_111805_1 | J21: coal transportation from nlc talabira mines to ntpc kudgi through rcr | K21: Coal transport (RCR / siding) | L21: National Thermal Power Corporation Limited | M21: Karnataka | N21: Kudligi | O21: 46156 | P21: AOC | Q21: Kalyani Ventures Limited | S21: 1 named / 1 | T21: 1.5 | U21: =IF(ISNUMBER(G21),MAX(MAX(G21,Settings!$B$13)*Settings!$B$7*Settings!$B$5,IF(ISNUMBER(Settings!$B$12),Settings!$B$12,0))*(1+IF(Settings!$B$11="Y",0,Settings!$B$10/100))+N(Settings!$B$9),"") | W21: =IF(ISNUMBER(V21),IF(V21*Settings!$B$8>1000,"beyond table",IFERROR(LOOKUP(V21*Settings!$B$8,'FOIS 145A'!$A$2:$A$22,'FOIS 145A'!$C$2:$C$22)*(1+IF(Settings!$B$11="Y",0,Settings!$B$10/100)),"")),"") | X21: =IF(AND(ISNUMBER(U21),ISNUMBER(W21)),U21+W21,"") | Y21: =Settings!$B$6
A22: Yes | B22: mine named in title; plant = tender city in West Bengal | C22: Talabira (near Sambalpur/Jharsuguda) | D22: 61 | G22: 61 | H22: 15407506 | I22: 2025_DVC_245419_1 | J22: lifting of 20.0(twenty) lmt coal from nlc india limited (nlcil)-talabira ii and iii ocp, sambalpur, odisha to dstps and other tps of dvc through rcr mode | K22: Coal transport (RCR / siding) | L22: Damodar Valley Corporation | M22: West Bengal | N22: Kolkata | O22: 45897 | P22: Technical | Q22: - | R22: Anoop Road Carriers, Godavari Commodities | S22: 5 named / 17 | U22: =IF(ISNUMBER(G22),MAX(MAX(G22,Settings!$B$13)*Settings!$B$7*Settings!$B$5,IF(ISNUMBER(Settings!$B$12),Settings!$B$12,0))*(1+IF(Settings!$B$11="Y",0,Settings!$B$10/100))+N(Settings!$B$9),"") | W22: =IF(ISNUMBER(V22),IF(V22*Settings!$B$8>1000,"beyond table",IFERROR(LOOKUP(V22*Settings!$B$8,'FOIS 145A'!$A$2:$A$22,'FOIS 145A'!$C$2:$C$22)*(1+IF(Settings!$B$11="Y",0,Settings!$B$10/100)),"")),"") | X22: =IF(AND(ISNUMBER(U22),ISNUMBER(W22)),U22+W22,"") | Y22: =Settings!$B$6
A23: Yes | B23: mine named in title | C23: Talabira (near Sambalpur/Jharsuguda) | D23: 61 | G23: 61 | H23: 14761261 | I23: 2025_NTPC_98583_1 | J23: transportation of 300000mt coal from nlc talabira mines of nlc ltd to ntpc simhadri under rcr mode through any nearby siding | K23: Coal transport (RCR / siding) | L23: National Thermal Power Corporation Limited | M23: Andhra Pradesh | N23: Visakhapatnam | O23: 45880 | P23: Technical | Q23: - | R23: Advika Logistics, Anoop Road Carriers, Indermani / Indramani | S23: 5 named / 15 | U23: =IF(ISNUMBER(G23),MAX(MAX(G23,Settings!$B$13)*Settings!$B$7*Settings!$B$5,IF(ISNUMBER(Settings!$B$12),Settings!$B$12,0))*(1+IF(Settings!$B$11="Y",0,Settings!$B$10/100))+N(Settings!$B$9),"") | W23: =IF(ISNUMBER(V23),IF(V23*Settings!$B$8>1000,"beyond table",IFERROR(LOOKUP(V23*Settings!$B$8,'FOIS 145A'!$A$2:$A$22,'FOIS 145A'!$C$2:$C$22)*(1+IF(Settings!$B$11="Y",0,Settings!$B$10/100)),"")),"") | X23: =IF(AND(ISNUMBER(U23),ISNUMBER(W23)),U23+W23,"") | Y23: =Settings!$B$6
A24: Yes | B24: mine named in title; plant/siding named in title | C24: Dharamjaigarh (Raigarh) | D24: 66 | E24: Dharamjaigarh (Raigarh) | F24: 66 | G24: 66 | H24: 15913239 | I24: GEM/2025/B/6876204 | J24: loading, transportation & unloading and wagon loading of coal from surface coal yard of tlcmp to kchp | K24: Coal transport (RCR / siding) | L24: National Thermal Power Corporation Limited | M24: Chhattisgarh | N24: Raigarh | O24: 45999 | P24: AOC | Q24: A B Carriers | R24: Anoop Road Carriers, Mohit Minerals, Nkas Services, Orissa Stevedores | S24: 5 named / 10 | T24: 9.08 | U24: =IF(ISNUMBER(G24),MAX(MAX(G24,Settings!$B$13)*Settings!$B$7*Settings!$B$5,IF(ISNUMBER(Settings!$B$12),Settings!$B$12,0))*(1+IF(Settings!$B$11="Y",0,Settings!$B$10/100))+N(Settings!$B$9),"") | W24: =IF(ISNUMBER(V24),IF(V24*Settings!$B$8>1000,"beyond table",IFERROR(LOOKUP(V24*Settings!$B$8,'FOIS 145A'!$A$2:$A$22,'FOIS 145A'!$C$2:$C$22)*(1+IF(Settings!$B$11="Y",0,Settings!$B$10/100)),"")),"") | X24: =IF(AND(ISNUMBER(U24),ISNUMBER(W24)),U24+W24,"") | Y24: =Settings!$B$6
A25: Yes | B25: mine named in title; plant = tender city in Maharashtra | C25: Dharamjaigarh (Raigarh) | D25: 66 | G25: 66 | H25: 14761268 | I25: 2025_NTPC_98502_1 | J25: coal transportation (20 lmt) from talaipalli mines to mouda stps under rcr mode via korichhapar siding | K25: Coal transport (RCR / siding) | L25: National Thermal Power Corporation Limited | M25: Maharashtra | N25: Nagpur | O25: 45870 | P25: Financial | Q25: - | R25: Anoop Road Carriers, Godavari Commodities, Indermani / Indramani | S25: 5 named / 20 | U25: =IF(ISNUMBER(G25),MAX(MAX(G25,Settings!$B$13)*Settings!$B$7*Settings!$B$5,IF(ISNUMBER(Settings!$B$12),Settings!$B$12,0))*(1+IF(Settings!$B$11="Y",0,Settings!$B$10/100))+N(Settings!$B$9),"") | W25: =IF(ISNUMBER(V25),IF(V25*Settings!$B$8>1000,"beyond table",IFERROR(LOOKUP(V25*Settings!$B$8,'FOIS 145A'!$A$2:$A$22,'FOIS 145A'!$C$2:$C$22)*(1+IF(Settings!$B$11="Y",0,Settings!$B$10/100)),"")),"") | X25: =IF(AND(ISNUMBER(U25),ISNUMBER(W25)),U25+W25,"") | Y25: =Settings!$B$6
A26: Yes | B26: plant/siding named in title | E26: Dharamjaigarh (Raigarh) | F26: 66 | G26: 66 | H26: 16814789 | I26: GEM/2026/B/7315717 | J26: coal transportation from ramnagore colliery to nspcl durgapur | K26: Coal transport (road) | L26: Ntpc-Sail Power Company Private Limited | M26: West Bengal | N26: Durgapur | O26: 46097 | P26: AOC | Q26: M/S United Coal Carriers | R26: United Coal Carriers | S26: 5 named / 5 | T26: 0.21 | U26: =IF(ISNUMBER(G26),MAX(MAX(G26,Settings!$B$13)*Settings!$B$7*Settings!$B$5,IF(ISNUMBER(Settings!$B$12),Settings!$B$12,0))*(1+IF(Settings!$B$11="Y",0,Settings!$B$10/100))+N(Settings!$B$9),"") | W26: =IF(ISNUMBER(V26),IF(V26*Settings!$B$8>1000,"beyond table",IFERROR(LOOKUP(V26*Settings!$B$8,'FOIS 145A'!$A$2:$A$22,'FOIS 145A'!$C$2:$C$22)*(1+IF(Settings!$B$11="Y",0,Settings!$B$10/100)),"")),"") | X26: =IF(AND(ISNUMBER(U26),ISNUMBER(W26)),U26+W26,"") | Y26: =Settings!$B$6
A27: Yes | B27: mine named in title | C27: Dharamjaigarh (Raigarh) | D27: 66 | G27: 66 | H27: 17065555 | I27: GEM/2026/B/7067958 | J27: handling service, handling & transport service, ob removal, coal extraction, composite work for ob removal cutting loading transportation wagon loading of coal at durgapur ocm r.. | K27: Mining services (OB / extraction) | L27: South Eastern Coalfields Limited | M27: Chhattisgarh | N27: Raigarh | O27: 46081 | P27: AOC | Q27: Sunil Kumar Agrawal | S27: 5 named / 11 | T27: 4247.08 | U27: =IF(ISNUMBER(G27),MAX(MAX(G27,Settings!$B$13)*Settings!$B$7*Settings!$B$5,IF(ISNUMBER(Settings!$B$12),Settings!$B$12,0))*(1+IF(Settings!$B$11="Y",0,Settings!$B$10/100))+N(Settings!$B$9),"") | W27: =IF(ISNUMBER(V27),IF(V27*Settings!$B$8>1000,"beyond table",IFERROR(LOOKUP(V27*Settings!$B$8,'FOIS 145A'!$A$2:$A$22,'FOIS 145A'!$C$2:$C$22)*(1+IF(Settings!$B$11="Y",0,Settings!$B$10/100)),"")),"") | X27: =IF(AND(ISNUMBER(U27),ISNUMBER(W27)),U27+W27,"") | Y27: =Settings!$B$6
A28: Yes | B28: mine = coal company's tender city; siding = same area | C28: Sambalpur (tender city) | D28: 77 | E28: Sambalpur (tender city) | F28: 77 | G28: 77 | H28: 12395907 | I28: GEM/2024/B/5759091 | J28: coal loading and transport | K28: Coal transport (road) | L28: Mahanadi Coalfields Limited | M28: Orissa | N28: Sambalpur | O28: 45670 | P28: AOC | Q28: Vlt Associates | S28: 5 named / 10 | T28: 28 | U28: =IF(ISNUMBER(G28),MAX(MAX(G28,Settings!$B$13)*Settings!$B$7*Settings!$B$5,IF(ISNUMBER(Settings!$B$12),Settings!$B$12,0))*(1+IF(Settings!$B$11="Y",0,Settings!$B$10/100))+N(Settings!$B$9),"") | W28: =IF(ISNUMBER(V28),IF(V28*Settings!$B$8>1000,"beyond table",IFERROR(LOOKUP(V28*Settings!$B$8,'FOIS 145A'!$A$2:$A$22,'FOIS 145A'!$C$2:$C$22)*(1+IF(Settings!$B$11="Y",0,Settings!$B$10/100)),"")),"") | X28: =IF(AND(ISNUMBER(U28),ISNUMBER(W28)),U28+W28,"") | Y28: =Settings!$B$6
A29: Yes | B29: mine = coal company's tender city; siding = same area | C29: Korba (tender city) | D29: 88 | E29: Korba (tender city) | F29: 88 | G29: 88 | H29: 16687336 | I29: GEM/2025/B/7005420 | J29: handling & transport service, transport service, handling service, hiring of pay loader and tippers for coal loading at saraipali transportation and loading into wagons at korba.. | K29: Coal transport (RCR / siding) | L29: South Eastern Coalfields Limited | M29: Chhattisgarh | N29: Korba | O29: 46024 | P29: AOC | Q29: G K Associates | R29: G K Associates | S29: 5 named / 30 | T29: 329.87 | U29: =IF(ISNUMBER(G29),MAX(MAX(G29,Settings!$B$13)*Settings!$B$7*Settings!$B$5,IF(ISNUMBER(Settings!$B$12),Settings!$B$12,0))*(1+IF(Settings!$B$11="Y",0,Settings!$B$10/100))+N(Settings!$B$9),"") | W29: =IF(ISNUMBER(V29),IF(V29*Settings!$B$8>1000,"beyond table",IFERROR(LOOKUP(V29*Settings!$B$8,'FOIS 145A'!$A$2:$A$22,'FOIS 145A'!$C$2:$C$22)*(1+IF(Settings!$B$11="Y",0,Settings!$B$10/100)),"")),"") | X29: =IF(AND(ISNUMBER(U29),ISNUMBER(W29)),U29+W29,"") | Y29: =Settings!$B$6
A30: Yes | B30: mine named in title; plant/siding named in title | C30: Korba | D30: 88 | E30: Korba | F30: 88 | G30: 88 | H30: 16125779 | I30: GEM/2025/B/6972824 | J30: handling & transport service, coal loading & transportation from saraipali ocm to srk rl siding, korba | K30: Coal transport (RCR / siding) | L30: South Eastern Coalfields Limited | M30: Chhattisgarh | N30: Korba | O30: 46013 | P30: AOC | Q30: M/S Chandan Kumar Singh | R30: G K Associates, Chandan Kumar Singh | S30: 5 named / 7 | T30: 1.58 | U30: =IF(ISNUMBER(G30),MAX(MAX(G30,Settings!$B$13)*Settings!$B$7*Settings!$B$5,IF(ISNUMBER(Settings!$B$12),Settings!$B$12,0))*(1+IF(Settings!$B$11="Y",0,Settings!$B$10/100))+N(Settings!$B$9),"") | W30: =IF(ISNUMBER(V30),IF(V30*Settings!$B$8>1000,"beyond table",IFERROR(LOOKUP(V30*Settings!$B$8,'FOIS 145A'!$A$2:$A$22,'FOIS 145A'!$C$2:$C$22)*(1+IF(Settings!$B$11="Y",0,Settings!$B$10/100)),"")),"") | X30: =IF(AND(ISNUMBER(U30),ISNUMBER(W30)),U30+W30,"") | Y30: =Settings!$B$6
A31: Yes | B31: mine named in title | C31: Korba | D31: 88 | G31: 88 | H31: 16687380 | I31: GEM/2026/B/7114126 | J31: hiring of pay loaders and tippers for mechanical loading and transportation of coal at dipka oc expansion project, dipka area, secl for a period of 1096 days | K31: Coal transport (road) | L31: South Eastern Coalfields Limited | M31: Chhattisgarh | N31: Korba | O31: 46053 | P31: AOC | Q31: Maa Parwati Transport | S31: 5 named / 9 | T31: 90.24 | U31: =IF(ISNUMBER(G31),MAX(MAX(G31,Settings!$B$13)*Settings!$B$7*Settings!$B$5,IF(ISNUMBER(Settings!$B$12),Settings!$B$12,0))*(1+IF(Settings!$B$11="Y",0,Settings!$B$10/100))+N(Settings!$B$9),"") | W31: =IF(ISNUMBER(V31),IF(V31*Settings!$B$8>1000,"beyond table",IFERROR(LOOKUP(V31*Settings!$B$8,'FOIS 145A'!$A$2:$A$22,'FOIS 145A'!$C$2:$C$22)*(1+IF(Settings!$B$11="Y",0,Settings!$B$10/100)),"")),"") | X31: =IF(AND(ISNUMBER(U31),ISNUMBER(W31)),U31+W31,"") | Y31: =Settings!$B$6
A32: Yes | B32: mine named in title | C32: Korba | D32: 88 | G32: 88 | H32: 16786403 | I32: GEM/2025/B/6972482 | J32: hiring of pay loader, mobile crusher and tippers for transportation of coal at gevra area secl | K32: Coal transport (road) | L32: South Eastern Coalfields Limited | M32: Chhattisgarh | N32: Korba | O32: 46023 | P32: AOC | Q32: Vikas Coal And Minerals Private Limited | R32: G K Associates | S32: 5 named / 16 | T32: 140.8 | U32: =IF(ISNUMBER(G32),MAX(MAX(G32,Settings!$B$13)*Settings!$B$7*Settings!$B$5,IF(ISNUMBER(Settings!$B$12),Settings!$B$12,0))*(1+IF(Settings!$B$11="Y",0,Settings!$B$10/100))+N(Settings!$B$9),"") | W32: =IF(ISNUMBER(V32),IF(V32*Settings!$B$8>1000,"beyond table",IFERROR(LOOKUP(V32*Settings!$B$8,'FOIS 145A'!$A$2:$A$22,'FOIS 145A'!$C$2:$C$22)*(1+IF(Settings!$B$11="Y",0,Settings!$B$10/100)),"")),"") | X32: =IF(AND(ISNUMBER(U32),ISNUMBER(W32)),U32+W32,"") | Y32: =Settings!$B$6
A33: Yes | B33: mine = coal company's tender city; siding = same area | C33: Korba (tender city) | D33: 88 | E33: Korba (tender city) | F33: 88 | G33: 88 | H33: 15830605 | I33: GEM/2025/B/6869302 | J33: loading and transportation of coal | K33: Coal transport (road) | L33: South Eastern Coalfields Limited | M33: Chhattisgarh | N33: Korba | O33: 45989 | P33: AOC | Q33: G K Associates | R33: G K Associates | S33: 3 named / 3 | T33: 1.67 | U33: =IF(ISNUMBER(G33),MAX(MAX(G33,Settings!$B$13)*Settings!$B$7*Settings!$B$5,IF(ISNUMBER(Settings!$B$12),Settings!$B$12,0))*(1+IF(Settings!$B$11="Y",0,Settings!$B$10/100))+N(Settings!$B$9),"") | W33: =IF(ISNUMBER(V33),IF(V33*Settings!$B$8>1000,"beyond table",IFERROR(LOOKUP(V33*Settings!$B$8,'FOIS 145A'!$A$2:$A$22,'FOIS 145A'!$C$2:$C$22)*(1+IF(Settings!$B$11="Y",0,Settings!$B$10/100)),"")),"") | X33: =IF(AND(ISNUMBER(U33),ISNUMBER(W33)),U33+W33,"") | Y33: =Settings!$B$6
A34: Yes | B34: mine = coal company's tender city; siding = same area | C34: Korba (tender city) | D34: 88 | E34: Korba (tender city) | F34: 88 | G34: 88 | H34: 14287776 | I34: GEM/2025/B/6337006 | J34: loading and transportation | K34: Coal transport (road) | L34: South Eastern Coalfields Limited | M34: Chhattisgarh | N34: Korba | O34: 45836 | P34: AOC | Q34: Rakesh Kumar Enterprises | R34: G K Associates | S34: 5 named / 6 | T34: 1.9 | U34: =IF(ISNUMBER(G34),MAX(MAX(G34,Settings!$B$13)*Settings!$B$7*Settings!$B$5,IF(ISNUMBER(Settings!$B$12),Settings!$B$12,0))*(1+IF(Settings!$B$11="Y",0,Settings!$B$10/100))+N(Settings!$B$9),"") | W34: =IF(ISNUMBER(V34),IF(V34*Settings!$B$8>1000,"beyond table",IFERROR(LOOKUP(V34*Settings!$B$8,'FOIS 145A'!$A$2:$A$22,'FOIS 145A'!$C$2:$C$22)*(1+IF(Settings!$B$11="Y",0,Settings!$B$10/100)),"")),"") | X34: =IF(AND(ISNUMBER(U34),ISNUMBER(W34)),U34+W34,"") | Y34: =Settings!$B$6
A35: Yes | B35: mine named in title | C35: Korba | D35: 88 | G35: 88 | H35: 17670369 | I35: GEM/2026/B/7435893 | J35: handling service, excavator with crusher bucket system with screening and loading of coal into tippers at kusmunda oc kusmunda area | K35: Loading / handling / crushing | L35: South Eastern Coalfields Limited | M35: Chhattisgarh | N35: Korba | O35: 46156 | P35: AOC | Q35: Fsnl Private Limited, Maa Sarwamangla Transport Company | S35: 5 named / 8 | T35: 24.94 | U35: =IF(ISNUMBER(G35),MAX(MAX(G35,Settings!$B$13)*Settings!$B$7*Settings!$B$5,IF(ISNUMBER(Settings!$B$12),Settings!$B$12,0))*(1+IF(Settings!$B$11="Y",0,Settings!$B$10/100))+N(Settings!$B$9),"") | W35: =IF(ISNUMBER(V35),IF(V35*Settings!$B$8>1000,"beyond table",IFERROR(LOOKUP(V35*Settings!$B$8,'FOIS 145A'!$A$2:$A$22,'FOIS 145A'!$C$2:$C$22)*(1+IF(Settings!$B$11="Y",0,Settings!$B$10/100)),"")),"") | X35: =IF(AND(ISNUMBER(U35),ISNUMBER(W35)),U35+W35,"") | Y35: =Settings!$B$6
A36: Yes | B36: mine = coal company's tender city; siding = same area | C36: Korba (tender city) | D36: 88 | E36: Korba (tender city) | F36: 88 | G36: 88 | H36: 15659451 | I36: GEM/2025/B/6627991 | J36: handling service, transpor | K36: Loading / handling / crushing | L36: South Eastern Coalfields Limited | M36: Chhattisgarh | N36: Korba | O36: 45923 | P36: AOC | Q36: Harsh Roadlines Private Limited | R36: Orissa Stevedores | S36: 5 named / 8 | T36: 82.78 | U36: =IF(ISNUMBER(G36),MAX(MAX(G36,Settings!$B$13)*Settings!$B$7*Settings!$B$5,IF(ISNUMBER(Settings!$B$12),Settings!$B$12,0))*(1+IF(Settings!$B$11="Y",0,Settings!$B$10/100))+N(Settings!$B$9),"") | W36: =IF(ISNUMBER(V36),IF(V36*Settings!$B$8>1000,"beyond table",IFERROR(LOOKUP(V36*Settings!$B$8,'FOIS 145A'!$A$2:$A$22,'FOIS 145A'!$C$2:$C$22)*(1+IF(Settings!$B$11="Y",0,Settings!$B$10/100)),"")),"") | X36: =IF(AND(ISNUMBER(U36),ISNUMBER(W36)),U36+W36,"") | Y36: =Settings!$B$6
A37: Yes | B37: mine = coal company's tender city; siding = same area | C37: Korba (tender city) | D37: 88 | E37: Korba (tender city) | F37: 88 | G37: 88 | H37: 17304517 | I37: GEM/2026/B/7372908 | J37: handling service, transport service, handling & transport service, ob removal, composite work for ob removal coal cutting by surface miner and loading and transportation of coal.. | K37: Mining services (OB / extraction) | L37: South Eastern Coalfields Limited | M37: Chhattisgarh | N37: Korba | O37: 46135 | P37: AOC | Q37: Knr Constructions Limited | S37: 5 named / 8 | T37: 3966.12 | U37: =IF(ISNUMBER(G37),MAX(MAX(G37,Settings!$B$13)*Settings!$B$7*Settings!$B$5,IF(ISNUMBER(Settings!$B$12),Settings!$B$12,0))*(1+IF(Settings!$B$11="Y",0,Settings!$B$10/100))+N(Settings!$B$9),"") | W37: =IF(ISNUMBER(V37),IF(V37*Settings!$B$8>1000,"beyond table",IFERROR(LOOKUP(V37*Settings!$B$8,'FOIS 145A'!$A$2:$A$22,'FOIS 145A'!$C$2:$C$22)*(1+IF(Settings!$B$11="Y",0,Settings!$B$10/100)),"")),"") | X37: =IF(AND(ISNUMBER(U37),ISNUMBER(W37)),U37+W37,"") | Y37: =Settings!$B$6
A38: Yes | B38: mine named in title | C38: Korba | D38: 88 | G38: 88 | H38: 16765105 | I38: GEM/2025/B/7003673 | J38: ob removal, handling & transport service, hiring of hemm for ob removal and coal drilling with loading and transportation at manikpur ocp korba area | K38: Mining services (OB / extraction) | L38: South Eastern Coalfields Limited | M38: Chhattisgarh | N38: Korba | O38: 46043 | P38: AOC | Q38: Orissa Stevedores Limited | S38: 5 named / 10 | T38: 1775.85 | U38: =IF(ISNUMBER(G38),MAX(MAX(G38,Settings!$B$13)*Settings!$B$7*Settings!$B$5,IF(ISNUMBER(Settings!$B$12),Settings!$B$12,0))*(1+IF(Settings!$B$11="Y",0,Settings!$B$10/100))+N(Settings!$B$9),"") | W38: =IF(ISNUMBER(V38),IF(V38*Settings!$B$8>1000,"beyond table",IFERROR(LOOKUP(V38*Settings!$B$8,'FOIS 145A'!$A$2:$A$22,'FOIS 145A'!$C$2:$C$22)*(1+IF(Settings!$B$11="Y",0,Settings!$B$10/100)),"")),"") | X38: =IF(AND(ISNUMBER(U38),ISNUMBER(W38)),U38+W38,"") | Y38: =Settings!$B$6
A39: Yes | B39: mine = coal company's tender city; siding = same area | C39: Korba (tender city) | D39: 88 | E39: Korba (tender city) | F39: 88 | G39: 88 | H39: 16245601 | I39: GEM/2025/B/6729097 | J39: hiring of pay loader incorporated with weight sensors for mechanical transfer of coal into railway wagons for a quantity of 17520000 te with minimum tpd16000 te for a period of .. | K39: Other | L39: South Eastern Coalfields Limited | M39: Chhattisgarh | N39: Korba | O39: 45948 | P39: AOC | Q39: Sat Kartar Logistics | S39: 5 named / 19 | T39: 14.89 | U39: =IF(ISNUMBER(G39),MAX(MAX(G39,Settings!$B$13)*Settings!$B$7*Settings!$B$5,IF(ISNUMBER(Settings!$B$12),Settings!$B$12,0))*(1+IF(Settings!$B$11="Y",0,Settings!$B$10/100))+N(Settings!$B$9),"") | W39: =IF(ISNUMBER(V39),IF(V39*Settings!$B$8>1000,"beyond table",IFERROR(LOOKUP(V39*Settings!$B$8,'FOIS 145A'!$A$2:$A$22,'FOIS 145A'!$C$2:$C$22)*(1+IF(Settings!$B$11="Y",0,Settings!$B$10/100)),"")),"") | X39: =IF(AND(ISNUMBER(U39),ISNUMBER(W39)),U39+W39,"") | Y39: =Settings!$B$6
A40: Yes | B40: mine = coal company's tender city; siding = same area | C40: Korba (tender city) | D40: 88 | E40: Korba (tender city) | F40: 88 | G40: 88 | H40: 12743621 | I40: GEM/2025/B/5926593 | J40: hiring of payloaders and t | K40: Other | L40: South Eastern Coalfields Limited | M40: Chhattisgarh | N40: Korba | O40: 45712 | P40: AOC | Q40: Harsh Roadlines Private Limited | S40: 5 named / 7 | T40: 2.41 | U40: =IF(ISNUMBER(G40),MAX(MAX(G40,Settings!$B$13)*Settings!$B$7*Settings!$B$5,IF(ISNUMBER(Settings!$B$12),Settings!$B$12,0))*(1+IF(Settings!$B$11="Y",0,Settings!$B$10/100))+N(Settings!$B$9),"") | W40: =IF(ISNUMBER(V40),IF(V40*Settings!$B$8>1000,"beyond table",IFERROR(LOOKUP(V40*Settings!$B$8,'FOIS 145A'!$A$2:$A$22,'FOIS 145A'!$C$2:$C$22)*(1+IF(Settings!$B$11="Y",0,Settings!$B$10/100)),"")),"") | X40: =IF(AND(ISNUMBER(U40),ISNUMBER(W40)),U40+W40,"") | Y40: =Settings!$B$6
...

Sheet Edge summary
A1: Category | B1: Edge: Yes | C1: Borderline | D1: Unknown | E1: No | F1: Edge Yes awarded Rs Cr (sum)
A2: Coal supply | B2: =COUNTIFS(Master!$K$2:$K$321,$A2,Master!$A$2:$A$321,"Yes") | C2: =COUNTIFS(Master!$K$2:$K$321,$A2,Master!$A$2:$A$321,"Borderline") | D2: =COUNTIFS(Master!$K$2:$K$321,$A2,Master!$A$2:$A$321,"Unknown") | E2: =COUNTIFS(Master!$K$2:$K$321,$A2,Master!$A$2:$A$321,"No") | F2: =SUMIFS(Master!$T$2:$T$321,Master!$K$2:$K$321,$A2,Master!$A$2:$A$321,"Yes")
A3: Coal transport (RCR / siding) | B3: =COUNTIFS(Master!$K$2:$K$321,$A3,Master!$A$2:$A$321,"Yes") | C3: =COUNTIFS(Master!$K$2:$K$321,$A3,Master!$A$2:$A$321,"Borderline") | D3: =COUNTIFS(Master!$K$2:$K$321,$A3,Master!$A$2:$A$321,"Unknown") | E3: =COUNTIFS(Master!$K$2:$K$321,$A3,Master!$A$2:$A$321,"No") | F3: =SUMIFS(Master!$T$2:$T$321,Master!$K$2:$K$321,$A3,Master!$A$2:$A$321,"Yes")
A4: Coal transport (road) | B4: =COUNTIFS(Master!$K$2:$K$321,$A4,Master!$A$2:$A$321,"Yes") | C4: =COUNTIFS(Master!$K$2:$K$321,$A4,Master!$A$2:$A$321,"Borderline") | D4: =COUNTIFS(Master!$K$2:$K$321,$A4,Master!$A$2:$A$321,"Unknown") | E4: =COUNTIFS(Master!$K$2:$K$321,$A4,Master!$A$2:$A$321,"No") | F4: =SUMIFS(Master!$T$2:$T$321,Master!$K$2:$K$321,$A4,Master!$A$2:$A$321,"Yes")
A5: Loading / handling / crushing | B5: =COUNTIFS(Master!$K$2:$K$321,$A5,Master!$A$2:$A$321,"Yes") | C5: =COUNTIFS(Master!$K$2:$K$321,$A5,Master!$A$2:$A$321,"Borderline") | D5: =COUNTIFS(Master!$K$2:$K$321,$A5,Master!$A$2:$A$321,"Unknown") | E5: =COUNTIFS(Master!$K$2:$K$321,$A5,Master!$A$2:$A$321,"No") | F5: =SUMIFS(Master!$T$2:$T$321,Master!$K$2:$K$321,$A5,Master!$A$2:$A$321,"Yes")
A6: Mining services (OB / extraction) | B6: =COUNTIFS(Master!$K$2:$K$321,$A6,Master!$A$2:$A$321,"Yes") | C6: =COUNTIFS(Master!$K$2:$K$321,$A6,Master!$A$2:$A$321,"Borderline") | D6: =COUNTIFS(Master!$K$2:$K$321,$A6,Master!$A$2:$A$321,"Unknown") | E6: =COUNTIFS(Master!$K$2:$K$321,$A6,Master!$A$2:$A$321,"No") | F6: =SUMIFS(Master!$T$2:$T$321,Master!$K$2:$K$321,$A6,Master!$A$2:$A$321,"Yes")
A7: Other | B7: =COUNTIFS(Master!$K$2:$K$321,$A7,Master!$A$2:$A$321,"Yes") | C7: =COUNTIFS(Master!$K$2:$K$321,$A7,Master!$A$2:$A$321,"Borderline") | D7: =COUNTIFS(Master!$K$2:$K$321,$A7,Master!$A$2:$A$321,"Unknown") | E7: =COUNTIFS(Master!$K$2:$K$321,$A7,Master!$A$2:$A$321,"No") | F7: =SUMIFS(Master!$T$2:$T$321,Master!$K$2:$K$321,$A7,Master!$A$2:$A$321,"Yes")
A8: Other (biomass / coke) | B8: =COUNTIFS(Master!$K$2:$K$321,$A8,Master!$A$2:$A$321,"Yes") | C8: =COUNTIFS(Master!$K$2:$K$321,$A8,Master!$A$2:$A$321,"Borderline") | D8: =COUNTIFS(Master!$K$2:$K$321,$A8,Master!$A$2:$A$321,"Unknown") | E8: =COUNTIFS(Master!$K$2:$K$321,$A8,Master!$A$2:$A$321,"No") | F8: =SUMIFS(Master!$T$2:$T$321,Master!$K$2:$K$321,$A8,Master!$A$2:$A$321,"Yes")
A9: Washery / beneficiation | B9: =COUNTIFS(Master!$K$2:$K$321,$A9,Master!$A$2:$A$321,"Yes") | C9: =COUNTIFS(Master!$K$2:$K$321,$A9,Master!$A$2:$A$321,"Borderline") | D9: =COUNTIFS(Master!$K$2:$K$321,$A9,Master!$A$2:$A$321,"Unknown") | E9: =COUNTIFS(Master!$K$2:$K$321,$A9,Master!$A$2:$A$321,"No") | F9: =SUMIFS(Master!$T$2:$T$321,Master!$K$2:$K$321,$A9,Master!$A$2:$A$321,"Yes")
A10: Total | B10: =SUM(B2:B9) | C10: =SUM(C2:C9) | D10: =SUM(D2:D9) | E10: =SUM(E2:E9) | F10: =SUM(F2:F9)

Sheet Settings
A2: Setting | B2: Value | C2: Note
A3: Road rate Rs per tonne-km (YOUR NUMBER) | B3: 5 | C3: Aman, chat 2026-10-12: approx Rs 5 per tonne per km (approximate, not a written quote). Clear to use the illustrative rate.
A4: Illustrative road Rs per tonne-km | B4: 2.75 | C4: Indicative general-truck range Rs 2.0-3.5. NOT a coal quote.
A5: Road rate used | B5: =IF(ISNUMBER(B3),B3,B4)
A6: Rate status | B6: =IF(ISNUMBER(B3),"Your quote","ILLUSTRATIVE - replace with your quote")
A7: Road km = straight-line x | B7: 1.3 | C7: Typical road winding factor [UNVERIFIED].
A8: Rail km = straight-line x | B8: 1.2 | C8: Typical rail winding factor [UNVERIFIED]. FOIS charges on railway chargeable distance.
A9: Loading + unloading Rs per tonne (per handling) | C9: Blank counts as 0.
A10: GST on freight % | B10: 5 | C10: Per the FOIS calculator note.
A11: Take GST credit? (Y/N) | B11: N | C11: Y removes GST from the cost.
A12: Minimum road Rs per tonne | C12: Blank = no minimum.
A13: Minimum haul km | B13: 25 | C13: Floor for a same-town haul [UNVERIFIED].
A14: Edge radius km | B14: 150 | C14: Your rule: 150 km.
A15: Reference point | B15: Raigarh town (siding station not yet given) | C15: Give me your siding's railway station and I will re-run from it.

Sheet FOIS 145A
A1: From km | B1: To km | C1: Rs per tonne (base, train load)
A2: 1 | B2: 100 | C2: 216
A3: 101 | B3: 125 | C3: 389.6
A4: 126 | B4: 150 | C4: 448.9
A5: 151 | B5: 175 | C5: 488.7
A6: 176 | B6: 200 | C6: 532.2
A7: 201 | B7: 275 | C7: 672.5
A8: 276 | B8: 350 | C8: 797.2
A9: 351 | B9: 425 | C9: 926
A10: 426 | B10: 500 | C10: 1054.7
A11: 501 | B11: 600 | C11: 1228
A12: 601 | B12: 700 | C12: 1398.7
A13: 701 | B13: 730 | C13: 1435.6
... A22: 971 | B22: 1000 | C22: 1891.8
A24: FOIS rate class 145A train load, base tariff, read 2026-10-12

Sheet Competitors
A1: Group | B1: Competitor | C1: Tenders bid (export) | D1: Wins (export) | E1: Won Rs Cr (export) | F1: Wins in this sheet | G1: Wins on EDGE tenders (Yes) | H1: Edge tenders they won, Rs Cr
A2: User's 15 | B2: Godavari Commodities | C2: 60 | D2: 4 | E2: 282.37 | F2: =COUNTIF(Master!$Q$2:$Q$321,"*"&IFERROR(LEFT(B2,FIND(" /",B2)-1),B2)&"*") | G2: =COUNTIFS(Master!$Q$2:$Q$321,"*"&IFERROR(LEFT(B2,FIND(" /",B2)-1),B2)&"*",Master!$A$2:$A$321,"Yes") | H2: =SUMIFS(Master!$T$2:$T$321,Master!$Q$2:$Q$321,"*"&IFERROR(LEFT(B2,FIND(" /",B2)-1),B2)&"*",Master!$A$2:$A$321,"Yes")
A3: Other (recommended) | B3: G K Associates | C3: 40 | D3: 5 | E3: 374.77 | F3: =COUNTIF(Master!$Q$2:$Q$321,"*"&IFERROR(LEFT(B3,FIND(" /",B3)-1),B3)&"*") | G3: =COUNTIFS(Master!$Q$2:$Q$321,"*"&IFERROR(LEFT(B3,FIND(" /",B3)-1),B3)&"*",Master!$A$2:$A$321,"Yes") | H3: =SUMIFS(Master!$T$2:$T$321,Master!$Q$2:$Q$321,"*"&IFERROR(LEFT(B3,FIND(" /",B3)-1),B3)&"*",Master!$A$2:$A$321,"Yes")
A4: User's 15 | B4: Mohit Minerals | C4: 24 | D4: 5 | E4: 793.62 | F4: =COUNTIF(Master!$Q$2:$Q$321,"*"&IFERROR(LEFT(B4,FIND(" /",B4)-1),B4)&"*") | G4: =COUNTIFS(Master!$Q$2:$Q$321,"*"&IFERROR(LEFT(B4,FIND(" /",B4)-1),B4)&"*",Master!$A$2:$A$321,"Yes") | H4: =SUMIFS(Master!$T$2:$T$321,Master!$Q$2:$Q$321,"*"&IFERROR(LEFT(B4,FIND(" /",B4)-1),B4)&"*",Master!$A$2:$A$321,"Yes")
A5: User's 15 | B5: Anoop Road Carriers | C5: 19 | D5: 0 | E5: 0 | F5: =COUNTIF(Master!$Q$2:$Q$321,"*"&IFERROR(LEFT(B5,FIND(" /",B5)-1),B5)&"*") | G5: =COUNTIFS(Master!$Q$2:$Q$321,"*"&IFERROR(LEFT(B5,FIND(" /",B5)-1),B5)&"*",Master!$A$2:$A$321,"Yes") | H5: =SUMIFS(Master!$T$2:$T$321,Master!$Q$2:$Q$321,"*"&IFERROR(LEFT(B5,FIND(" /",B5)-1),B5)&"*",Master!$A$2:$A$321,"Yes")
A6: Other (recommended) | B6: Nkas Services | C6: 19 | D6: 0 | E6: 0 | F6: =COUNTIF(Master!$Q$2:$Q$321,"*"&IFERROR(LEFT(B6,FIND(" /",B6)-1),B6)&"*") | G6: =COUNTIFS(Master!$Q$2:$Q$321,"*"&IFERROR(LEFT(B6,FIND(" /",B6)-1),B6)&"*",Master!$A$2:$A$321,"Yes") | H6: =SUMIFS(Master!$T$2:$T$321,Master!$Q$2:$Q$321,"*"&IFERROR(LEFT(B6,FIND(" /",B6)-1),B6)&"*",Master!$A$2:$A$321,"Yes")
A7: Other (recommended) | B7: Chandan Kumar Singh | C7: 15 | D7: 4 | E7: 11.95 | F7: =COUNTIF(Master!$Q$2:$Q$321,"*"&IFERROR(LEFT(B7,FIND(" /",B7)-1),B7)&"*") | G7: =COUNTIFS(Master!$Q$2:$Q$321,"*"&IFERROR(LEFT(B7,FIND(" /",B7)-1),B7)&"*",Master!$A$2:$A$321,"Yes") | H7: =SUMIFS(Master!$T$2:$T$321,Master!$Q$2:$Q$321,"*"&IFERROR(LEFT(B7,FIND(" /",B7)-1),B7)&"*",Master!$A$2:$A$321,"Yes")
A8: Other (recommended) | B8: Sangita Sales | C8: 15 | D8: 1 | E8: 1.16 | F8: =COUNTIF(Master!$Q$2:$Q$321,"*"&IFERROR(LEFT(B8,FIND(" /",B8)-1),B8)&"*") | G8: =COUNTIFS(Master!$Q$2:$Q$321,"*"&IFERROR(LEFT(B8,FIND(" /",B8)-1),B8)&"*",Master!$A$2:$A$321,"Yes") | H8: =SUMIFS(Master!$T$2:$T$321,Master!$Q$2:$Q$321,"*"&IFERROR(LEFT(B8,FIND(" /",B8)-1),B8)&"*",Master!$A$2:$A$321,"Yes")
A9: Other (recommended) | B9: Bharat Road Carrier | C9: 14 | D9: 3 | E9: 16.67 | F9: =COUNTIF(Master!$Q$2:$Q$321,"*"&IFERROR(LEFT(B9,FIND(" /",B9)-1),B9)&"*") | G9: =COUNTIFS(Master!$Q$2:$Q$321,"*"&IFERROR(LEFT(B9,FIND(" /",B9)-1),B9)&"*",Master!$A$2:$A$321,"Yes") | H9: =SUMIFS(Master!$T$2:$T$321,Master!$Q$2:$Q$321,"*"&IFERROR(LEFT(B9,FIND(" /",B9)-1),B9)&"*",Master!$A$2:$A$321,"Yes")
A10: Other (recommended) | B10: Saikrupa Coal Supplier | C10: 14 | D10: 2 | E10: 34.97 | F10: =COUNTIF(Master!$Q$2:$Q$321,"*"&IFERROR(LEFT(B10,FIND(" /",B10)-1),B10)&"*") | G10: =COUNTIFS(Master!$Q$2:$Q$321,"*"&IFERROR(LEFT(B10,FIND(" /",B10)-1),B10)&"*",Master!$A$2:$A$321,"Yes") | H10: =SUMIFS(Master!$T$2:$T$321,Master!$Q$2:$Q$321,"*"&IFERROR(LEFT(B10,FIND(" /",B10)-1),B10)&"*",Master!$A$2:$A$321,"Yes")
A11: Tender247 shortlist | B11: United Coal Carriers | C11: 14 | D11: 4 | E11: 4.23 | F11: =COUNTIF(Master!$Q$2:$Q$321,"*"&IFERROR(LEFT(B11,FIND(" /",B11)-1),B11)&"*") | G11: =COUNTIFS(Master!$Q$2:$Q$321,"*"&IFERROR(LEFT(B11,FIND(" /",B11)-1),B11)&"*",Master!$A$2:$A$321,"Yes") | H11: =SUMIFS(Master!$T$2:$T$321,Master!$Q$2:$Q$321,"*"&IFERROR(LEFT(B11,FIND(" /",B11)-1),B11)&"*",Master!$A$2:$A$321,"Yes")
A12: User's 15 | B12: Indermani / Indramani | C12: 12 | D12: 2 | E12: 512.64 | F12: =COUNTIF(Master!$Q$2:$Q$321,"*"&IFERROR(LEFT(B12,FIND(" /",B12)-1),B12)&"*") | G12: =COUNTIFS(Master!$Q$2:$Q$321,"*"&IFERROR(LEFT(B12,FIND(" /",B12)-1),B12)&"*",Master!$A$2:$A$321,"Yes") | H12: =SUMIFS(Master!$T$2:$T$321,Master!$Q$2:$Q$321,"*"&IFERROR(LEFT(B12,FIND(" /",B12)-1),B12)&"*",Master!$A$2:$A$321,"Yes")
A13: Tender247 shortlist | B13: Caliber Mining and Logistics | C13: 8 | D13: 2 | E13: 2947.85 | F13: =COUNTIF(Master!$Q$2:$Q$321,"*"&IFERROR(LEFT(B13,FIND(" /",B13)-1),B13)&"*") | G13: =COUNTIFS(Master!$Q$2:$Q$321,"*"&IFERROR(LEFT(B13,FIND(" /",B13)-1),B13)&"*",Master!$A$2:$A$321,"Yes") | H13: =SUMIFS(Master!$T$2:$T$321,Master!$Q$2:$Q$321,"*"&IFERROR(LEFT(B13,FIND(" /",B13)-1),B13)&"*",Master!$A$2:$A$321,"Yes")
... A23: Tender247 shortlist | B23: Vedvyas Logistic | C23: 1 | D23: 0 | E23: 0 | F23: =COUNTIF(Master!$Q$2:$Q$321,"*"&IFERROR(LEFT(B23,FIND(" /",B23)-1),B23)&"*") | G23: =COUNTIFS(Master!$Q$2:$Q$321,"*"&IFERROR(LEFT(B23,FIND(" /",B23)-1),B23)&"*",Master!$A$2:$A$321,"Yes") | H23: =SUMIFS(Master!$T$2:$T$321,Master!$Q$2:$Q$321,"*"&IFERROR(LEFT(B23,FIND(" /",B23)-1),B23)&"*",Master!$A$2:$A$321,"Yes")
A25: Names match the Tender247 winner spelling; counts can differ from the export when spellings differ.
